2024-08-19 21:13:34,543 ERROR scheduler Exception in Enqueue Events for Site mysite.local
Traceback (most recent call last):
  File "/Users/vutuandung/my-bench1/apps/frappe/frappe/utils/scheduler.py", line 75, in enqueue_events_for_site
    if is_scheduler_inactive():
       ^^^^^^^^^^^^^^^^^^^^^^^
  File "/Users/vutuandung/my-bench1/apps/frappe/frappe/utils/scheduler.py", line 117, in is_scheduler_inactive
    if is_scheduler_disabled(verbose=verbose):
       ^^^^^^^^^^^^^^^^^^^^^^^^^^^^^^^^^^^^^^
  File "/Users/vutuandung/my-bench1/apps/frappe/frappe/utils/scheduler.py", line 130, in is_scheduler_disabled
    frappe.db.get_single_value("System Settings", "enable_scheduler")
  File "/Users/vutuandung/my-bench1/apps/frappe/frappe/database/database.py", line 841, in get_single_value
    ).run()
      ^^^^^
  File "/Users/vutuandung/my-bench1/apps/frappe/frappe/query_builder/utils.py", line 87, in execute_query
    result = frappe.db.sql(query, params, *args, **kwargs)  # nosemgrep
             ^^^^^^^^^^^^^^^^^^^^^^^^^^^^^^^^^^^^^^^^^^^^^
  File "/Users/vutuandung/my-bench1/apps/frappe/frappe/database/database.py", line 211, in sql
    self.connect()
  File "/Users/vutuandung/my-bench1/apps/frappe/frappe/database/database.py", line 117, in connect
    self._conn: "MariadbConnection" | "PostgresConnection" = self.get_connection()
                                                             ^^^^^^^^^^^^^^^^^^^^^
  File "/Users/vutuandung/my-bench1/apps/frappe/frappe/database/mariadb/database.py", line 107, in get_connection
    conn = self._get_connection()
           ^^^^^^^^^^^^^^^^^^^^^^
  File "/Users/vutuandung/my-bench1/apps/frappe/frappe/database/mariadb/database.py", line 113, in _get_connection
    return self.create_connection()
           ^^^^^^^^^^^^^^^^^^^^^^^^
  File "/Users/vutuandung/my-bench1/apps/frappe/frappe/database/mariadb/database.py", line 116, in create_connection
    return pymysql.connect(**self.get_connection_settings())
           ^^^^^^^^^^^^^^^^^^^^^^^^^^^^^^^^^^^^^^^^^^^^^^^^^
  File "/Users/vutuandung/my-bench1/env/lib/python3.12/site-packages/pymysql/connections.py", line 361, in __init__
    self.connect()
  File "/Users/vutuandung/my-bench1/env/lib/python3.12/site-packages/pymysql/connections.py", line 669, in connect
    self._request_authentication()
  File "/Users/vutuandung/my-bench1/env/lib/python3.12/site-packages/pymysql/connections.py", line 957, in _request_authentication
    auth_packet = self._read_packet()
                  ^^^^^^^^^^^^^^^^^^^
  File "/Users/vutuandung/my-bench1/env/lib/python3.12/site-packages/pymysql/connections.py", line 775, in _read_packet
    packet.raise_for_error()
  File "/Users/vutuandung/my-bench1/env/lib/python3.12/site-packages/pymysql/protocol.py", line 219, in raise_for_error
    err.raise_mysql_exception(self._data)
  File "/Users/vutuandung/my-bench1/env/lib/python3.12/site-packages/pymysql/err.py", line 150, in raise_mysql_exception
    raise errorclass(errno, errval)
pymysql.err.OperationalError: (1045, "Access denied for user '_321c2833f2006e86'@'localhost' (using password: YES)")
2024-08-19 21:14:34,580 ERROR scheduler Exception in Enqueue Events for Site mysite.local
Traceback (most recent call last):
  File "/Users/vutuandung/my-bench1/apps/frappe/frappe/utils/scheduler.py", line 75, in enqueue_events_for_site
    if is_scheduler_inactive():
       ^^^^^^^^^^^^^^^^^^^^^^^
  File "/Users/vutuandung/my-bench1/apps/frappe/frappe/utils/scheduler.py", line 117, in is_scheduler_inactive
    if is_scheduler_disabled(verbose=verbose):
       ^^^^^^^^^^^^^^^^^^^^^^^^^^^^^^^^^^^^^^
  File "/Users/vutuandung/my-bench1/apps/frappe/frappe/utils/scheduler.py", line 130, in is_scheduler_disabled
    frappe.db.get_single_value("System Settings", "enable_scheduler")
  File "/Users/vutuandung/my-bench1/apps/frappe/frappe/database/database.py", line 841, in get_single_value
    ).run()
      ^^^^^
  File "/Users/vutuandung/my-bench1/apps/frappe/frappe/query_builder/utils.py", line 87, in execute_query
    result = frappe.db.sql(query, params, *args, **kwargs)  # nosemgrep
             ^^^^^^^^^^^^^^^^^^^^^^^^^^^^^^^^^^^^^^^^^^^^^
  File "/Users/vutuandung/my-bench1/apps/frappe/frappe/database/database.py", line 211, in sql
    self.connect()
  File "/Users/vutuandung/my-bench1/apps/frappe/frappe/database/database.py", line 117, in connect
    self._conn: "MariadbConnection" | "PostgresConnection" = self.get_connection()
                                                             ^^^^^^^^^^^^^^^^^^^^^
  File "/Users/vutuandung/my-bench1/apps/frappe/frappe/database/mariadb/database.py", line 107, in get_connection
    conn = self._get_connection()
           ^^^^^^^^^^^^^^^^^^^^^^
  File "/Users/vutuandung/my-bench1/apps/frappe/frappe/database/mariadb/database.py", line 113, in _get_connection
    return self.create_connection()
           ^^^^^^^^^^^^^^^^^^^^^^^^
  File "/Users/vutuandung/my-bench1/apps/frappe/frappe/database/mariadb/database.py", line 116, in create_connection
    return pymysql.connect(**self.get_connection_settings())
           ^^^^^^^^^^^^^^^^^^^^^^^^^^^^^^^^^^^^^^^^^^^^^^^^^
  File "/Users/vutuandung/my-bench1/env/lib/python3.12/site-packages/pymysql/connections.py", line 361, in __init__
    self.connect()
  File "/Users/vutuandung/my-bench1/env/lib/python3.12/site-packages/pymysql/connections.py", line 669, in connect
    self._request_authentication()
  File "/Users/vutuandung/my-bench1/env/lib/python3.12/site-packages/pymysql/connections.py", line 957, in _request_authentication
    auth_packet = self._read_packet()
                  ^^^^^^^^^^^^^^^^^^^
  File "/Users/vutuandung/my-bench1/env/lib/python3.12/site-packages/pymysql/connections.py", line 775, in _read_packet
    packet.raise_for_error()
  File "/Users/vutuandung/my-bench1/env/lib/python3.12/site-packages/pymysql/protocol.py", line 219, in raise_for_error
    err.raise_mysql_exception(self._data)
  File "/Users/vutuandung/my-bench1/env/lib/python3.12/site-packages/pymysql/err.py", line 150, in raise_mysql_exception
    raise errorclass(errno, errval)
pymysql.err.OperationalError: (1045, "Access denied for user '_321c2833f2006e86'@'localhost' (using password: YES)")
2024-08-19 21:15:34,836 ERROR scheduler Exception in Enqueue Events for Site mysite.local
Traceback (most recent call last):
  File "/Users/vutuandung/my-bench1/apps/frappe/frappe/utils/scheduler.py", line 75, in enqueue_events_for_site
    if is_scheduler_inactive():
       ^^^^^^^^^^^^^^^^^^^^^^^
  File "/Users/vutuandung/my-bench1/apps/frappe/frappe/utils/scheduler.py", line 117, in is_scheduler_inactive
    if is_scheduler_disabled(verbose=verbose):
       ^^^^^^^^^^^^^^^^^^^^^^^^^^^^^^^^^^^^^^
  File "/Users/vutuandung/my-bench1/apps/frappe/frappe/utils/scheduler.py", line 130, in is_scheduler_disabled
    frappe.db.get_single_value("System Settings", "enable_scheduler")
  File "/Users/vutuandung/my-bench1/apps/frappe/frappe/database/database.py", line 841, in get_single_value
    ).run()
      ^^^^^
  File "/Users/vutuandung/my-bench1/apps/frappe/frappe/query_builder/utils.py", line 87, in execute_query
    result = frappe.db.sql(query, params, *args, **kwargs)  # nosemgrep
             ^^^^^^^^^^^^^^^^^^^^^^^^^^^^^^^^^^^^^^^^^^^^^
  File "/Users/vutuandung/my-bench1/apps/frappe/frappe/database/database.py", line 211, in sql
    self.connect()
  File "/Users/vutuandung/my-bench1/apps/frappe/frappe/database/database.py", line 117, in connect
    self._conn: "MariadbConnection" | "PostgresConnection" = self.get_connection()
                                                             ^^^^^^^^^^^^^^^^^^^^^
  File "/Users/vutuandung/my-bench1/apps/frappe/frappe/database/mariadb/database.py", line 107, in get_connection
    conn = self._get_connection()
           ^^^^^^^^^^^^^^^^^^^^^^
  File "/Users/vutuandung/my-bench1/apps/frappe/frappe/database/mariadb/database.py", line 113, in _get_connection
    return self.create_connection()
           ^^^^^^^^^^^^^^^^^^^^^^^^
  File "/Users/vutuandung/my-bench1/apps/frappe/frappe/database/mariadb/database.py", line 116, in create_connection
    return pymysql.connect(**self.get_connection_settings())
           ^^^^^^^^^^^^^^^^^^^^^^^^^^^^^^^^^^^^^^^^^^^^^^^^^
  File "/Users/vutuandung/my-bench1/env/lib/python3.12/site-packages/pymysql/connections.py", line 361, in __init__
    self.connect()
  File "/Users/vutuandung/my-bench1/env/lib/python3.12/site-packages/pymysql/connections.py", line 669, in connect
    self._request_authentication()
  File "/Users/vutuandung/my-bench1/env/lib/python3.12/site-packages/pymysql/connections.py", line 957, in _request_authentication
    auth_packet = self._read_packet()
                  ^^^^^^^^^^^^^^^^^^^
  File "/Users/vutuandung/my-bench1/env/lib/python3.12/site-packages/pymysql/connections.py", line 775, in _read_packet
    packet.raise_for_error()
  File "/Users/vutuandung/my-bench1/env/lib/python3.12/site-packages/pymysql/protocol.py", line 219, in raise_for_error
    err.raise_mysql_exception(self._data)
  File "/Users/vutuandung/my-bench1/env/lib/python3.12/site-packages/pymysql/err.py", line 150, in raise_mysql_exception
    raise errorclass(errno, errval)
pymysql.err.OperationalError: (1045, "Access denied for user '_321c2833f2006e86'@'localhost' (using password: YES)")
